<?xml version="1.0" encoding="utf-8"?>
<mujoco>
    <compiler angle="radian" coordinate="local" meshdir="../stls/fetch" texturedir="../textures"></compiler>
    <option timestep="0.002">
        <flag warmstart="enable"></flag>
    </option>

    <include file="shared.xml"></include>
    
    <worldbody>
        <geom name="floor0" pos="0.8 0.75 0" size="1.0 1.0 1" type="plane" condim="3" material="floor_mat"></geom>
        <body name="floor0" pos="0.8 0.75 0">
            <site name="target0" pos="0 0 0.5" size="0.02 0.02 0.02" rgba="1 0 0 1" type="sphere"></site>
        </body>

        <include file="robot.xml"></include>

        <body pos="1.3 0.75 0.2" name="table0">
            <geom size="0.4 0.65 0.2" type="box" mass="100000" material="table_mat"></geom>
        </body>
        
        <body pos="1.3590809675455 0.66800575574845 0.413264352407" name="object0">
            <light castshadow="false"/>
            <geom type="mesh" density="2959.22662233" rgba="1 1 1 1" material="object" mesh="object_mesh" conaffinity="0" contype="1"/>
            <joint type="slide" damping="1.8706155113466632" name="obj_slidex" axis="1 0 0" pos="0 0 0" range="-0.22 0.22"/>
            <joint type="slide" damping="1.8706155113466632" name="obj_slidey" axis="0 1 0" pos="0 0 0" range="-0.35 0.35"/>
            <site name="object0" pos="0.015919032454499993 0.01699424425155005 0.006735647592999994" size="0.002 0.002 0.002" rgba="1 0 0 0" type="sphere"></site>
        </body>

        <light directional="true" ambient="0.2 0.2 0.2" diffuse="0.8 0.8 0.8" specular="0.3 0.3 0.3" castshadow="false" pos="0 0 4" dir="0 0 -1" name="light0"></light>
    </worldbody>

    <asset>
        <mesh scale="0.000964789845725 0.000964789845725 0.000964789845725" file="mujoco_models/WillTankGrey.stl" name="object_mesh"/>
        <texture file="textures/obj_textures/stained_0051.png" name="object"/>
        <material specular="1" texture="object" rgba="0.9 0.9 0.9 1" shininess="0.3" name="object"/>
    </asset>
    
    <actuator></actuator>
</mujoco>
    