<?xml version="1.0" encoding="utf-8"?>
<mujoco>
    <compiler angle="radian" coordinate="local" meshdir="../stls/fetch" texturedir="../textures"></compiler>
    <option timestep="0.002">
        <flag warmstart="enable"></flag>
    </option>

    <include file="shared.xml"></include>
    
    <worldbody>
        <geom name="floor0" pos="0.8 0.75 0" size="1.0 1.0 1" type="plane" condim="3" material="floor_mat"></geom>
        <body name="floor0" pos="0.8 0.75 0">
            <site name="target0" pos="0 0 0.5" size="0.02 0.02 0.02" rgba="1 0 0 1" type="sphere"></site>
        </body>

        <include file="robot.xml"></include>

        <body pos="1.3 0.75 0.2" name="table0">
            <geom size="0.4 0.65 0.2" type="box" mass="100000" material="table_mat"></geom>
        </body>
        
        <body pos="1.3809614424635 0.6996137088578045 0.4130000004394999" name="object0">
            <light castshadow="false"/>
            <geom type="mesh" density="760.728267443" rgba="1 1 1 1" material="object" mesh="object_mesh" conaffinity="0" contype="1"/>
            <joint type="slide" damping="3.247979901810946" name="obj_slidex" axis="1 0 0" pos="0 0 0" range="-0.22 0.22"/>
            <joint type="slide" damping="3.247979901810946" name="obj_slidey" axis="0 1 0" pos="0 0 0" range="-0.35 0.35"/>
            <site name="object0" pos="-0.005961442463499944 -0.014613708857804442 0.00699999956050007" size="0.002 0.002 0.002" rgba="1 0 0 0" type="sphere"></site>
        </body>

        <light directional="true" ambient="0.2 0.2 0.2" diffuse="0.8 0.8 0.8" specular="0.3 0.3 0.3" castshadow="false" pos="0 0 4" dir="0 0 -1" name="light0"></light>
    </worldbody>

    <asset>
        <mesh scale="0.00123068544289 0.00123068544289 0.00123068544289" file="mujoco_models/Love_Box_1.stl" name="object_mesh"/>
        <texture file="textures/obj_textures/smeared_0073.png" name="object"/>
        <material specular="1" texture="object" rgba="0.9 0.9 0.9 1" shininess="0.3" name="object"/>
    </asset>
    
    <actuator></actuator>
</mujoco>
    